Workbook

Sheet 00_Read_Me
A1: MWG FP&A Showcase — Monthly Reporting, Variance & Rolling Forecast | B1: MWG FP&A Showcase — Monthly Reporting, Variance & Rolling Forecast | C1: MWG FP&A Showcase — Monthly Reporting, Variance & Rolling Forecast | D1: MWG FP&A Showcase — Monthly Reporting, Variance & Rolling Forecast | E1: MWG FP&A Showcase — Monthly Reporting, Variance & Rolling Forecast | F1: MWG FP&A Showcase — Monthly Reporting, Variance & Rolling Forecast | G1: MWG FP&A Showcase — Monthly Reporting, Variance & Rolling Forecast | H1: MWG FP&A Showcase — Monthly Reporting, Variance & Rolling Forecast | I1: MWG FP&A Showcase — Monthly Reporting, Variance & Rolling Forecast | J1: MWG FP&A Showcase — Monthly Reporting, Variance & Rolling Forecast
A2: CV work sample | FY2024/FY2025 actuals tie to audited filings; Budget and Forecast are analyst-prepared and clearly labelled. | B2: CV work sample | FY2024/FY2025 actuals tie to audited filings; Budget and Forecast are analyst-prepared and clearly labelled. | C2: CV work sample | FY2024/FY2025 actuals tie to audited filings; Budget and Forecast are analyst-prepared and clearly labelled. | D2: CV work sample | FY2024/FY2025 actuals tie to audited filings; Budget and Forecast are analyst-prepared and clearly labelled. | E2: CV work sample | FY2024/FY2025 actuals tie to audited filings; Budget and Forecast are analyst-prepared and clearly labelled. | F2: CV work sample | FY2024/FY2025 actuals tie to audited filings; Budget and Forecast are analyst-prepared and clearly labelled. | G2: CV work sample | FY2024/FY2025 actuals tie to audited filings; Budget and Forecast are analyst-prepared and clearly labelled. | H2: CV work sample | FY2024/FY2025 actuals tie to audited filings; Budget and Forecast are analyst-prepared and clearly labelled. | I2: CV work sample | FY2024/FY2025 actuals tie to audited filings; Budget and Forecast are analyst-prepared and clearly labelled. | J2: CV work sample | FY2024/FY2025 actuals tie to audited filings; Budget and Forecast are analyst-prepared and clearly labelled.
A4: Workbook purpose and scope | B4: Workbook purpose and scope | C4: Workbook purpose and scope | D4: Workbook purpose and scope | E4: Workbook purpose and scope | F4: Workbook purpose and scope | G4: Workbook purpose and scope | H4: Workbook purpose and scope | I4: Workbook purpose and scope | J4: Workbook purpose and scope
A5: Purpose | B5: Demonstrate Excel / FP&A skills using public MWG disclosures: monthly reporting, budget variance, forecast, working capital, dashboard and controls.
A6: Core management question | B6: Did FY2025 beat plan, which business units drove the variance, and what H2 growth is required for FY2026 guidance?
A7: Actual period | B7: FY2024 and FY2025 actual P&L; 6M2026 reported revenue.
A8: Budget period | B8: FY2025 and FY2026 analyst-prepared monthly budgets calibrated to MWG official revenue and PAT targets.
A9: Forecast period | B9: FY2026 rolling forecast as of Jun-2026 with Base / Bull / Bear scenario selector.
A10: Units | B10: VND bn unless stated otherwise.
A11: Data limitation | B11: MWG does not publish a monthly cost-center ledger or segment P&L. Quarterly expenses are allocated to months and BUs by revenue; do not present allocated BU margins as company-reported.
A12: Refresh layer | B12: Queries reference workbook input tables; outputs remain formula-driven even if Power Query is not refreshed.
A13: Owner / version | B13: Le Hoang Nghia | v1.2 | 28 Jul 2026
A15: How to use | B15: How to use | C15: How to use | D15: How to use | E15: How to use | F15: How to use | G15: How to use | H15: How to use | I15: How to use | J15: How to use
A16: 1) Refresh or replace the two raw input tables. 2) Review account and BU mappings. 3) Read Monthly P&L, YoY Analysis and Variance Analysis. 4) Change the scenario in Rolling Forecast cell B3. 5) Review Forecast vs Budget and working-capital assumptions. 6) Confirm MODEL STATUS = PASS before sharing. 7) Use the PivotTable on Variance Analysis to filter Revenue / Opex by BU and version.
A22: Financial-model color legend | B22: Financial-model color legend | C22: Financial-model color legend | D22: Financial-model color legend | E22: Financial-model color legend | F22: Financial-model color legend | G22: Financial-model color legend | H22: Financial-model color legend | I22: Financial-model color legend | J22: Financial-model color legend
A23: Blue font | B23: Editable assumptions / scenario inputs
A24: Green font | B24: Formula linked to another worksheet
A25: Black font | B25: Formula or calculation on the same worksheet
A26: Yellow fill | B26: Key assumption / limitation requiring attention
A27: Green or red fill | B27: Control status or favorable / unfavorable output
A29: Model status | B29: Model status | C29: Model status | D29: Model status | E29: Model status | F29: Model status | G29: Model status | H29: Model status | I29: Model status | J29: Model status
A30: MODEL STATUS | B30: ='10_Checks'!B2 -> PASS
A31: Checks passed | B31: =COUNTIF('10_Checks'!F6:F21,"PASS") -> 16
A32: Checks failed | B32: =COUNTIF('10_Checks'!F6:F21,"FAIL") -> 0
A34: Learning mode (optional; does not affect the core model) | B34: Learning mode (optional; does not affect the core model) | C34: Learning mode (optional; does not affect the core model) | D34: Learning mode (optional; does not affect the core model) | E34: Learning mode (optional; does not affect the core model) | F34: Learning mode (optional; does not affect the core model) | G34: Learning mode (optional; does not affect the core model) | H34: Learning mode (optional; does not affect the core model) | I34: Learning mode (optional; does not affect the core model) | J34: Learning mode (optional; does not affect the core model)
A35: Use 14_Formula_Guide to understand the logic and formula patterns used across the workbook. Then complete the blue/yellow formula cells in 15_Practice_Lab and use the automatic status column to check your work. Open 16_Answer_Key only after attempting the exercises. Practice formulas are isolated and do not feed the management reports or model checks.

Sheet 01_Raw_Actual
A1: Actual input table — FY2024/FY2025 audited P&L and 6M2026 reported revenue | B1: Actual input table — FY2024/FY2025 audited P&L and 6M2026 reported revenue | C1: Actual input table — FY2024/FY2025 audited P&L and 6M2026 reported revenue | D1: Actual input table — FY2024/FY2025 audited P&L and 6M2026 reported revenue | E1: Actual input table — FY2024/FY2025 audited P&L and 6M2026 reported revenue | F1: Actual input table — FY2024/FY2025 audited P&L and 6M2026 reported revenue | G1: Actual input table — FY2024/FY2025 audited P&L and 6M2026 reported revenue | H1: Actual input table — FY2024/FY2025 audited P&L and 6M2026 reported revenue | I1: Actual input table — FY2024/FY2025 audited P&L and 6M2026 reported revenue | J1: Actual input table — FY2024/FY2025 audited P&L and 6M2026 reported revenue | K1: Actual input table — FY2024/FY2025 audited P&L and 6M2026 reported revenue
A2: Green formula columns use XLOOKUP against 04_Account_Mapping. Input values are intentionally separate from report outputs. | B2: Green formula columns use XLOOKUP against 04_Account_Mapping. Input values are intentionally separate from report outputs. | C2: Green formula columns use XLOOKUP against 04_Account_Mapping. Input values are intentionally separate from report outputs. | D2: Green formula columns use XLOOKUP against 04_Account_Mapping. Input values are intentionally separate from report outputs. | E2: Green formula columns use XLOOKUP against 04_Account_Mapping. Input values are intentionally separate from report outputs. | F2: Green formula columns use XLOOKUP against 04_Account_Mapping. Input values are intentionally separate from report outputs. | G2: Green formula columns use XLOOKUP against 04_Account_Mapping. Input values are intentionally separate from report outputs. | H2: Green formula columns use XLOOKUP against 04_Account_Mapping. Input values are intentionally separate from report outputs. | I2: Green formula columns use XLOOKUP against 04_Account_Mapping. Input values are intentionally separate from report outputs. | J2: Green formula columns use XLOOKUP against 04_Account_Mapping. Input values are intentionally separate from report outputs. | K2: Green formula columns use XLOOKUP against 04_Account_Mapping. Input values are intentionally separate from report outputs.
A5: Period | B5: Year | C5: Month | D5: BusinessUnit | E5: CostCenter | F5: AccountCode | G5: Amount_VNDm | H5: EvidenceClass | I5: SourceID | J5: MappedCategory | K5: CostNature
A6: 45292 | B6: 2024 | C6: 1 | D6: Group | E6: CC_GROUP | F6: REV | G6: 10806.512 | H6: Reported monthly revenue; scaled to audited FY2024 revenue | I6: SRC-005 | J6: =_xlfn.XLOOKUP(F6,'04_Account_Mapping'!$A$6:$A$14,'04_Account_Mapping'!$C$6:$C$14,"Unmapped",0) -> Revenue | K6: =_xlfn.XLOOKUP(F6,'04_Account_Mapping'!$A$6:$A$14,'04_Account_Mapping'!$D$6:$D$14,"Unmapped",0) -> Income
A7: 45292 | B7: 2024 | C7: 1 | D7: Group | E7: CC_GROUP | F7: COGS | G7: -8594.4533 | H7: Audited FY2024 account allocated monthly by reported revenue | I7: SRC-005 | J7: =_xlfn.XLOOKUP(F7,'04_Account_Mapping'!$A$6:$A$14,'04_Account_Mapping'!$C$6:$C$14,"Unmapped",0) -> COGS | K7: =_xlfn.XLOOKUP(F7,'04_Account_Mapping'!$A$6:$A$14,'04_Account_Mapping'!$D$6:$D$14,"Unmapped",0) -> Expense
A8: 45292 | B8: 2024 | C8: 1 | D8: Group | E8: CC_GROUP | F8: SELL | G8: -1596.7372 | H8: Audited FY2024 account allocated monthly by reported revenue | I8: SRC-005 | J8: =_xlfn.XLOOKUP(F8,'04_Account_Mapping'!$A$6:$A$14,'04_Account_Mapping'!$C$6:$C$14,"Unmapped",0) -> Selling Expense | K8: =_xlfn.XLOOKUP(F8,'04_Account_Mapping'!$A$6:$A$14,'04_Account_Mapping'!$D$6:$D$14,"Unmapped",0) -> Expense
A9: 45292 | B9: 2024 | C9: 1 | D9: Group | E9: CC_GROUP | F9: GA | G9: -286.83326 | H9: Audited FY2024 account allocated monthly by reported revenue | I9: SRC-005 | J9: =_xlfn.XLOOKUP(F9,'04_Account_Mapping'!$A$6:$A$14,'04_Account_Mapping'!$C$6:$C$14,"Unmapped",0) -> G&A | K9: =_xlfn.XLOOKUP(F9,'04_Account_Mapping'!$A$6:$A$14,'04_Account_Mapping'!$D$6:$D$14,"Unmapped",0) -> Expense
A10: 45292 | B10: 2024 | C10: 1 | D10: Group | E10: CC_GROUP | F10: FIN_INC | G10: 191.16781 | H10: Audited FY2024 account allocated monthly by reported revenue | I10: SRC-005 | J10: =_xlfn.XLOOKUP(F10,'04_Account_Mapping'!$A$6:$A$14,'04_Account_Mapping'!$C$6:$C$14,"Unmapped",0) -> Finance Income | K10: =_xlfn.XLOOKUP(F10,'04_Account_Mapping'!$A$6:$A$14,'04_Account_Mapping'!$D$6:$D$14,"Unmapped",0) -> Income
A11: 45292 | B11: 2024 | C11: 1 | D11: Group | E11: CC_GROUP | F11: FIN_EXP | G11: -95.601146 | H11: Audited FY2024 account allocated monthly by reported revenue | I11: SRC-005 | J11: =_xlfn.XLOOKUP(F11,'04_Account_Mapping'!$A$6:$A$14,'04_Account_Mapping'!$C$6:$C$14,"Unmapped",0) -> Finance Expense | K11: =_xlfn.XLOOKUP(F11,'04_Account_Mapping'!$A$6:$A$14,'04_Account_Mapping'!$D$6:$D$14,"Unmapped",0) -> Expense
A12: 45292 | B12: 2024 | C12: 1 | D12: Group | E12: CC_GROUP | F12: JV | G12: -3.5873753 | H12: Audited FY2024 account allocated monthly by reported revenue | I12: SRC-005 | J12: =_xlfn.XLOOKUP(F12,'04_Account_Mapping'!$A$6:$A$14,'04_Account_Mapping'!$C$6:$C$14,"Unmapped",0) -> JV Profit/(Loss) | K12: =_xlfn.XLOOKUP(F12,'04_Account_Mapping'!$A$6:$A$14,'04_Account_Mapping'!$D$6:$D$14,"Unmapped",0) -> Income
A13: 45292 | B13: 2024 | C13: 1 | D13: Group | E13: CC_GROUP | F13: OTHER | G13: -32.279486 | H13: Audited FY2024 account allocated monthly by reported revenue | I13: SRC-005 | J13: =_xlfn.XLOOKUP(F13,'04_Account_Mapping'!$A$6:$A$14,'04_Account_Mapping'!$C$6:$C$14,"Unmapped",0) -> Other Net | K13: =_xlfn.XLOOKUP(F13,'04_Account_Mapping'!$A$6:$A$14,'04_Account_Mapping'!$D$6:$D$14,"Unmapped",0) -> Income
A14: 45292 | B14: 2024 | C14: 1 | D14: Group | E14: CC_GROUP | F14: TAX | G14: -87.879566 | H14: Audited FY2024 account allocated monthly by reported revenue | I14: SRC-005 | J14: =_xlfn.XLOOKUP(F14,'04_Account_Mapping'!$A$6:$A$14,'04_Account_Mapping'!$C$6:$C$14,"Unmapped",0) -> Tax Expense | K14: =_xlfn.XLOOKUP(F14,'04_Account_Mapping'!$A$6:$A$14,'04_Account_Mapping'!$D$6:$D$14,"Unmapped",0) -> Expense
A15: 45323 | B15: 2024 | C15: 2 | D15: Group | E15: CC_GROUP | F15: REV | G15: 10806.512 | H15: Reported monthly revenue; scaled to audited FY2024 revenue | I15: SRC-005 | J15: =_xlfn.XLOOKUP(F15,'04_Account_Mapping'!$A$6:$A$14,'04_Account_Mapping'!$C$6:$C$14,"Unmapped",0) -> Revenue | K15: =_xlfn.XLOOKUP(F15,'04_Account_Mapping'!$A$6:$A$14,'04_Account_Mapping'!$D$6:$D$14,"Unmapped",0) -> Income
A16: 45323 | B16: 2024 | C16: 2 | D16: Group | E16: CC_GROUP | F16: COGS | G16: -8594.4533 | H16: Audited FY2024 account allocated monthly by reported revenue | I16: SRC-005 | J16: =_xlfn.XLOOKUP(F16,'04_Account_Mapping'!$A$6:$A$14,'04_Account_Mapping'!$C$6:$C$14,"Unmapped",0) -> COGS | K16: =_xlfn.XLOOKUP(F16,'04_Account_Mapping'!$A$6:$A$14,'04_Account_Mapping'!$D$6:$D$14,"Unmapped",0) -> Expense
A17: 45323 | B17: 2024 | C17: 2 | D17: Group | E17: CC_GROUP | F17: SELL | G17: -1596.7372 | H17: Audited FY2024 account allocated monthly by reported revenue | I17: SRC-005 | J17: =_xlfn.XLOOKUP(F17,'04_Account_Mapping'!$A$6:$A$14,'04_Account_Mapping'!$C$6:$C$14,"Unmapped",0) -> Selling Expense | K17: =_xlfn.XLOOKUP(F17,'04_Account_Mapping'!$A$6:$A$14,'04_Account_Mapping'!$D$6:$D$14,"Unmapped",0) -> Expense
... A569: 46174 | B569: 2026 | C569: 6 | D569: Other | E569: CC_NEWVENTURES | F569: REV | G569: 322.92 | H569: Reported cumulative revenue; monthly delta | I569: SRC-007 | J569: =_xlfn.XLOOKUP(F569,'04_Account_Mapping'!$A$6:$A$14,'04_Account_Mapping'!$C$6:$C$14,"Unmapped",0) -> Revenue | K569: =_xlfn.XLOOKUP(F569,'04_Account_Mapping'!$A$6:$A$14,'04_Account_Mapping'!$D$6:$D$14,"Unmapped",0) -> Income

Sheet 02_Raw_Budget
A1: Budget input table — analyst prepared and calibrated to FY2025/FY2026 official targets | B1: Budget input table — analyst prepared and calibrated to FY2025/FY2026 official targets | C1: Budget input table — analyst prepared and calibrated to FY2025/FY2026 official targets | D1: Budget input table — analyst prepared and calibrated to FY2025/FY2026 official targets | E1: Budget input table — analyst prepared and calibrated to FY2025/FY2026 official targets | F1: Budget input table — analyst prepared and calibrated to FY2025/FY2026 official targets | G1: Budget input table — analyst prepared and calibrated to FY2025/FY2026 official targets | H1: Budget input table — analyst prepared and calibrated to FY2025/FY2026 official targets | I1: Budget input table — analyst prepared and calibrated to FY2025/FY2026 official targets | J1: Budget input table — analyst prepared and calibrated to FY2025/FY2026 official targets | K1: Budget input table — analyst prepared and calibrated to FY2025/FY2026 official targets
A2: Green formula columns use XLOOKUP against 04_Account_Mapping. Input values are intentionally separate from report outputs. | B2: Green formula columns use XLOOKUP against 04_Account_Mapping. Input values are intentionally separate from report outputs. | C2: Green formula columns use XLOOKUP against 04_Account_Mapping. Input values are intentionally separate from report outputs. | D2: Green formula columns use XLOOKUP against 04_Account_Mapping. Input values are intentionally separate from report outputs. | E2: Green formula columns use XLOOKUP against 04_Account_Mapping. Input values are intentionally separate from report outputs. | F2: Green formula columns use XLOOKUP against 04_Account_Mapping. Input values are intentionally separate from report outputs. | G2: Green formula columns use XLOOKUP against 04_Account_Mapping. Input values are intentionally separate from report outputs. | H2: Green formula columns use XLOOKUP against 04_Account_Mapping. Input values are intentionally separate from report outputs. | I2: Green formula columns use XLOOKUP against 04_Account_Mapping. Input values are intentionally separate from report outputs. | J2: Green formula columns use XLOOKUP against 04_Account_Mapping. Input values are intentionally separate from report outputs. | K2: Green formula columns use XLOOKUP against 04_Account_Mapping. Input values are intentionally separate from report outputs.
A5: Period | B5: Year | C5: Month | D5: BusinessUnit | E5: CostCenter | F5: AccountCode | G5: Amount_VNDm | H5: EvidenceClass | I5: SourceID | J5: MappedCategory | K5: CostNature
A6: 45658 | B6: 2025 | C6: 1 | D6: TGDĐ | E6: CC_TECH | F6: REV | G6: 2654.547 | H6: Analyst-prepared monthly budget calibrated to official FY2025 revenue/PAT plan | I6: SRC-008 | J6: =_xlfn.XLOOKUP(F6,'04_Account_Mapping'!$A$6:$A$14,'04_Account_Mapping'!$C$6:$C$14,"Unmapped",0) -> Revenue | K6: =_xlfn.XLOOKUP(F6,'04_Account_Mapping'!$A$6:$A$14,'04_Account_Mapping'!$D$6:$D$14,"Unmapped",0) -> Income
A7: 45658 | B7: 2025 | C7: 1 | D7: TGDĐ | E7: CC_TECH | F7: COGS | G7: -2112.9752 | H7: Analyst-prepared monthly budget calibrated to official FY2025 revenue/PAT plan | I7: SRC-008 | J7: =_xlfn.XLOOKUP(F7,'04_Account_Mapping'!$A$6:$A$14,'04_Account_Mapping'!$C$6:$C$14,"Unmapped",0) -> COGS | K7: =_xlfn.XLOOKUP(F7,'04_Account_Mapping'!$A$6:$A$14,'04_Account_Mapping'!$D$6:$D$14,"Unmapped",0) -> Expense
A8: 45658 | B8: 2025 | C8: 1 | D8: TGDĐ | E8: CC_TECH | F8: SELL | G8: -376.94568 | H8: Analyst-prepared monthly budget calibrated to official FY2025 revenue/PAT plan | I8: SRC-008 | J8: =_xlfn.XLOOKUP(F8,'04_Account_Mapping'!$A$6:$A$14,'04_Account_Mapping'!$C$6:$C$14,"Unmapped",0) -> Selling Expense | K8: =_xlfn.XLOOKUP(F8,'04_Account_Mapping'!$A$6:$A$14,'04_Account_Mapping'!$D$6:$D$14,"Unmapped",0) -> Expense
A9: 45658 | B9: 2025 | C9: 1 | D9: TGDĐ | E9: CC_TECH | F9: GA | G9: -71.672769 | H9: Analyst-prepared monthly budget calibrated to official FY2025 revenue/PAT plan | I9: SRC-008 | J9: =_xlfn.XLOOKUP(F9,'04_Account_Mapping'!$A$6:$A$14,'04_Account_Mapping'!$C$6:$C$14,"Unmapped",0) -> G&A | K9: =_xlfn.XLOOKUP(F9,'04_Account_Mapping'!$A$6:$A$14,'04_Account_Mapping'!$D$6:$D$14,"Unmapped",0) -> Expense
A10: 45658 | B10: 2025 | C10: 1 | D10: TGDĐ | E10: CC_TECH | F10: FIN_INC | G10: 39.818205 | H10: Analyst-prepared monthly budget calibrated to official FY2025 revenue/PAT plan | I10: SRC-008 | J10: =_xlfn.XLOOKUP(F10,'04_Account_Mapping'!$A$6:$A$14,'04_Account_Mapping'!$C$6:$C$14,"Unmapped",0) -> Finance Income | K10: =_xlfn.XLOOKUP(F10,'04_Account_Mapping'!$A$6:$A$14,'04_Account_Mapping'!$D$6:$D$14,"Unmapped",0) -> Income
A11: 45658 | B11: 2025 | C11: 1 | D11: TGDĐ | E11: CC_TECH | F11: FIN_EXP | G11: -21.236376 | H11: Analyst-prepared monthly budget calibrated to official FY2025 revenue/PAT plan | I11: SRC-008 | J11: =_xlfn.XLOOKUP(F11,'04_Account_Mapping'!$A$6:$A$14,'04_Account_Mapping'!$C$6:$C$14,"Unmapped",0) -> Finance Expense | K11: =_xlfn.XLOOKUP(F11,'04_Account_Mapping'!$A$6:$A$14,'04_Account_Mapping'!$D$6:$D$14,"Unmapped",0) -> Expense
A12: 45658 | B12: 2025 | C12: 1 | D12: TGDĐ | E12: CC_TECH | F12: JV | G12: 0 | H12: Analyst-prepared monthly budget calibrated to official FY2025 revenue/PAT plan | I12: SRC-008 | J12: =_xlfn.XLOOKUP(F12,'04_Account_Mapping'!$A$6:$A$14,'04_Account_Mapping'!$C$6:$C$14,"Unmapped",0) -> JV Profit/(Loss) | K12: =_xlfn.XLOOKUP(F12,'04_Account_Mapping'!$A$6:$A$14,'04_Account_Mapping'!$D$6:$D$14,"Unmapped",0) -> Income
A13: 45658 | B13: 2025 | C13: 1 | D13: TGDĐ | E13: CC_TECH | F13: OTHER | G13: -4.2472752 | H13: Analyst-prepared monthly budget calibrated to official FY2025 revenue/PAT plan | I13: SRC-008 | J13: =_xlfn.XLOOKUP(F13,'04_Account_Mapping'!$A$6:$A$14,'04_Account_Mapping'!$C$6:$C$14,"Unmapped",0) -> Other Net | K13: =_xlfn.XLOOKUP(F13,'04_Account_Mapping'!$A$6:$A$14,'04_Account_Mapping'!$D$6:$D$14,"Unmapped",0) -> Income
A14: 45658 | B14: 2025 | C14: 1 | D14: TGDĐ | E14: CC_TECH | F14: TAX | G14: -21.457588 | H14: Analyst-prepared monthly budget calibrated to official FY2025 revenue/PAT plan | I14: SRC-008 | J14: =_xlfn.XLOOKUP(F14,'04_Account_Mapping'!$A$6:$A$14,'04_Account_Mapping'!$C$6:$C$14,"Unmapped",0) -> Tax Expense | K14: =_xlfn.XLOOKUP(F14,'04_Account_Mapping'!$A$6:$A$14,'04_Account_Mapping'!$D$6:$D$14,"Unmapped",0) -> Expense
A15: 45658 | B15: 2025 | C15: 1 | D15: ĐMX | E15: CC_TECH | F15: REV | G15: 5067.7716 | H15: Analyst-prepared monthly budget calibrated to official FY2025 revenue/PAT plan | I15: SRC-008 | J15: =_xlfn.XLOOKUP(F15,'04_Account_Mapping'!$A$6:$A$14,'04_Account_Mapping'!$C$6:$C$14,"Unmapped",0) -> Revenue | K15: =_xlfn.XLOOKUP(F15,'04_Account_Mapping'!$A$6:$A$14,'04_Account_Mapping'!$D$6:$D$14,"Unmapped",0) -> Income
A16: 45658 | B16: 2025 | C16: 1 | D16: ĐMX | E16: CC_TECH | F16: COGS | G16: -4033.8617 | H16: Analyst-prepared monthly budget calibrated to official FY2025 revenue/PAT plan | I16: SRC-008 | J16: =_xlfn.XLOOKUP(F16,'04_Account_Mapping'!$A$6:$A$14,'04_Account_Mapping'!$C$6:$C$14,"Unmapped",0) -> COGS | K16: =_xlfn.XLOOKUP(F16,'04_Account_Mapping'!$A$6:$A$14,'04_Account_Mapping'!$D$6:$D$14,"Unmapped",0) -> Expense
A17: 45658 | B17: 2025 | C17: 1 | D17: ĐMX | E17: CC_TECH | F17: SELL | G17: -719.62356 | H17: Analyst-prepared monthly budget calibrated to official FY2025 revenue/PAT plan | I17: SRC-008 | J17: =_xlfn.XLOOKUP(F17,'04_Account_Mapping'!$A$6:$A$14,'04_Account_Mapping'!$C$6:$C$14,"Unmapped",0) -> Selling Expense | K17: =_xlfn.XLOOKUP(F17,'04_Account_Mapping'!$A$6:$A$14,'04_Account_Mapping'!$D$6:$D$14,"Unmapped",0) -> Expense
... A869: 46357 | B869: 2026 | C869: 12 | D869: Other | E869: CC_NEWVENTURES | F869: TAX | G869: -4.6963206 | H869: Analyst monthly phasing calibrated to official FY2026 revenue/PAT plan | I869: SRC-009 | J869: =_xlfn.XLOOKUP(F869,'04_Account_Mapping'!$A$6:$A$14,'04_Account_Mapping'!$C$6:$C$14,"Unmapped",0) -> Tax Expense | K869: =_xlfn.XLOOKUP(F869,'04_Account_Mapping'!$A$6:$A$14,'04_Account_Mapping'!$D$6:$D$14,"Unmapped",0) -> Expense

Sheet 03_Master_Data
A1: Master Data, Scenario Drivers & Refresh Control | B1: Master Data, Scenario Drivers & Refresh Control | C1: Master Data, Scenario Drivers & Refresh Control | D1: Master Data, Scenario Drivers & Refresh Control | E1: Master Data, Scenario Drivers & Refresh Control | F1: Master Data, Scenario Drivers & Refresh Control | G1: Master Data, Scenario Drivers & Refresh Control | H1: Master Data, Scenario Drivers & Refresh Control
A2: Blue cells are user-editable assumptions. Company targets remain separate from analyst assumptions. | B2: Blue cells are user-editable assumptions. Company targets remain separate from analyst assumptions. | C2: Blue cells are user-editable assumptions. Company targets remain separate from analyst assumptions. | D2: Blue cells are user-editable assumptions. Company targets remain separate from analyst assumptions. | E2: Blue cells are user-editable assumptions. Company targets remain separate from analyst assumptions. | F2: Blue cells are user-editable assumptions. Company targets remain separate from analyst assumptions. | G2: Blue cells are user-editable assumptions. Company targets remain separate from analyst assumptions. | H2: Blue cells are user-editable assumptions. Company targets remain separate from analyst assumptions.
A4: Business unit and cost-center master | B4: Business unit and cost-center master | C4: Business unit and cost-center master | D4: Business unit and cost-center master | E4: Business unit and cost-center master | F4: Business unit and cost-center master | G4: Business unit and cost-center master | H4: Business unit and cost-center master
A6: BusinessUnit | B6: CostCenter | C6: Description | D6: FY2025 actual mix
A7: TGDĐ | B7: CC_TECH | C7: thegioididong.com + TopZone | D7: 0.239
A8: ĐMX | B8: CC_TECH | C8: Điện Máy Xanh | D8: 0.438
A9: BHX | B9: CC_GROCERY | C9: Bách Hóa Xanh | D9: 0.3
A10: Other | B10: CC_NEWVENTURES | C10: An Khang, AVAKids and other | D10: 0.023
A11: Group | B11: CC_GROUP | C11: FY2024 consolidated allocation only
A12: FY2025 budget assumptions | B12: FY2025 budget assumptions | C12: FY2025 budget assumptions | D12: FY2025 budget assumptions | E12: FY2026 plan / rolling forecast assumptions | F12: FY2026 plan / rolling forecast assumptions | G12: FY2026 plan / rolling forecast assumptions | H12: FY2026 plan / rolling forecast assumptions
A14: Driver | B14: Value | C14: Source / rationale | E14: Driver | F14: Value | G14: Source / rationale
A15: Revenue target | B15: 150000 | C15: Official MWG FY2025 guidance | E15: Revenue target | F15: 185000 | G15: Official MWG FY2026 guidance
A16: PAT target | B16: 4850 | C16: Official MWG FY2025 guidance | E16: PAT target | F16: 9200 | G16: Official MWG FY2026 guidance
A17: Selling expense / revenue | B17: 0.142 | C17: Analyst assumption | E17: Selling expense / revenue | F17: 0.122 | G17: Analyst assumption
A18: G&A / revenue | B18: 0.027 | C18: Analyst assumption | E18: G&A / revenue | F18: 0.029 | G18: Analyst assumption
A19: Finance income / revenue | B19: 0.015 | C19: Analyst assumption | E19: Finance income / revenue | F19: 0.02 | G19: Analyst assumption
A20: Finance expense / revenue | B20: 0.008 | C20: Analyst assumption | E20: Finance expense / revenue | F20: 0.01 | G20: Analyst assumption
A21: JV profit / revenue | B21: 0 | C21: Analyst assumption | E21: JV profit / revenue | F21: 0.0002 | G21: Analyst assumption
A22: Other net / revenue | B22: -0.0016 | C22: Analyst assumption | E22: Other net / revenue | F22: 0 | G22: Analyst assumption
A23: Tax rate | B23: 0.2 | C23: Analyst assumption | E23: Tax rate | F23: 0.2 | G23: Analyst assumption
A24: Implied gross margin | B24: =B16/(B15*(1-B23))+B17+B18-B19+B20-B21-B22 -> 0.20401667 | C24: Solved to make budget PAT equal official target | E24: Bull / Bear spread | F24: 0.05 | G24: ±5ppt H2 growth
E25: As-of month | F25: 6 | G25: Actual revenue through Jun-2026
E26: Implied gross margin | F26: =F16/(F15*(1-F23))+F17+F18-F19+F20-F21-F22 -> 0.20296216 | G26: Solved to make plan PAT equal official target
A28: Power Query objects expected in Queries & Connections | B28: Power Query objects expected in Queries & Connections | C28: Power Query objects expected in Queries & Connections | D28: Power Query objects expected in Queries & Connections | E28: Power Query objects expected in Queries & Connections | F28: Power Query objects expected in Queries & Connections | G28: Power Query objects expected in Queries & Connections | H28: Power Query objects expected in Queries & Connections
A30: Query | B30: Purpose | C30: Load type | D30: Status
A31: qActual_Clean | B31: Type and clean Actual input | C31: Connection only | D31: READY
A32: qBudget_Clean | B32: Type and clean Budget input | C32: Connection only | D32: READY
A33: qAccount_Map | B33: Type account mapping | C33: Connection only | D33: READY
A34: qActual_Mapped | B34: Merge Actual with mapping | C34: Connection only | D34: READY
A35: qCombined_Actual_Budget | B35: Append Actual and Budget | C35: Connection only | D35: READY

Sheet 04_Account_Mapping
A1: Account Mapping | B1: Account Mapping | C1: Account Mapping | D1: Account Mapping | E1: Account Mapping | F1: Account Mapping
A2: This mapping is used by XLOOKUP on raw inputs and by Power Query merge logic. | B2: This mapping is used by XLOOKUP on raw inputs and by Power Query merge logic. | C2: This mapping is used by XLOOKUP on raw inputs and by Power Query merge logic. | D2: This mapping is used by XLOOKUP on raw inputs and by Power Query merge logic. | E2: This mapping is used by XLOOKUP on raw inputs and by Power Query merge logic. | F2: This mapping is used by XLOOKUP on raw inputs and by Power Query merge logic.
A5: AccountCode | B5: AccountName | C5: P&L Category | D5: CostNature | E5: FavorableSign | F5: Variance rule
A6: REV | B6: Doanh thu thuần | C6: Revenue | D6: Income | E6: 1 | F6: Higher is favorable
A7: COGS | B7: Giá vốn hàng bán | C7: COGS | D7: Expense | E7: -1 | F7: Lower is favorable
A8: SELL | B8: Chi phí bán hàng | C8: Selling Expense | D8: Expense | E8: -1 | F8: Lower is favorable
A9: GA | B9: Chi phí quản lý doanh nghiệp | C9: G&A | D9: Expense | E9: -1 | F9: Lower is favorable
A10: FIN_INC | B10: Doanh thu tài chính | C10: Finance Income | D10: Income | E10: 1 | F10: Higher is favorable
A11: FIN_EXP | B11: Chi phí tài chính | C11: Finance Expense | D11: Expense | E11: -1 | F11: Lower is favorable
A12: JV | B12: Lãi/(lỗ) công ty liên doanh | C12: JV Profit/(Loss) | D12: Income | E12: 1 | F12: Higher is favorable
A13: OTHER | B13: Thu nhập/(chi phí) khác thuần | C13: Other Net | D13: Income | E13: 1 | F13: Higher is favorable
A14: TAX | B14: Thuế TNDN | C14: Tax Expense | D14: Expense | E14: -1 | F14: Lower is favorable

Sheet 05_Monthly_P&L
A1: Monthly P&L — FY2025 Actual vs Budget | B1: Monthly P&L — FY2025 Actual vs Budget | C1: Monthly P&L — FY2025 Actual vs Budget | D1: Monthly P&L — FY2025 Actual vs Budget | E1: Monthly P&L — FY2025 Actual vs Budget | F1: Monthly P&L — FY2025 Actual vs Budget | G1: Monthly P&L — FY2025 Actual vs Budget | H1: Monthly P&L — FY2025 Actual vs Budget | I1: Monthly P&L — FY2025 Actual vs Budget | J1: Monthly P&L — FY2025 Actual vs Budget | K1: Monthly P&L — FY2025 Actual vs Budget | L1: Monthly P&L — FY2025 Actual vs Budget | M1: Monthly P&L — FY2025 Actual vs Budget | N1: Monthly P&L — FY2025 Actual vs Budget | O1: Monthly P&L — FY2025 Actual vs Budget
A2: Actual quarterly totals tie to consolidated filings. Monthly and BU expense allocations use revenue weights because MWG does not disclose a monthly cost-center ledger. | B2: Actual quarterly totals tie to consolidated filings. Monthly and BU expense allocations use revenue weights because MWG does not disclose a monthly cost-center ledger. | C2: Actual quarterly totals tie to consolidated filings. Monthly and BU expense allocations use revenue weights because MWG does not disclose a monthly cost-center ledger. | D2: Actual quarterly totals tie to consolidated filings. Monthly and BU expense allocations use revenue weights because MWG does not disclose a monthly cost-center ledger. | E2: Actual quarterly totals tie to consolidated filings. Monthly and BU expense allocations use revenue weights because MWG does not disclose a monthly cost-center ledger. | F2: Actual quarterly totals tie to consolidated filings. Monthly and BU expense allocations use revenue weights because MWG does not disclose a monthly cost-center ledger. | G2: Actual quarterly totals tie to consolidated filings. Monthly and BU expense allocations use revenue weights because MWG does not disclose a monthly cost-center ledger. | H2: Actual quarterly totals tie to consolidated filings. Monthly and BU expense allocations use revenue weights because MWG does not disclose a monthly cost-center ledger. | I2: Actual quarterly totals tie to consolidated filings. Monthly and BU expense allocations use revenue weights because MWG does not disclose a monthly cost-center ledger. | J2: Actual quarterly totals tie to consolidated filings. Monthly and BU expense allocations use revenue weights because MWG does not disclose a monthly cost-center ledger. | K2: Actual quarterly totals tie to consolidated filings. Monthly and BU expense allocations use revenue weights because MWG does not disclose a monthly cost-center ledger. | L2: Actual quarterly totals tie to consolidated filings. Monthly and BU expense allocations use revenue weights because MWG does not disclose a monthly cost-center ledger. | M2: Actual quarterly totals tie to consolidated filings. Monthly and BU expense allocations use revenue weights because MWG does not disclose a monthly cost-center ledger. | N2: Actual quarterly totals tie to consolidated filings. Monthly and BU expense allocations use revenue weights because MWG does not disclose a monthly cost-center ledger. | O2: Actual quarterly totals tie to consolidated filings. Monthly and BU expense allocations use revenue weights because MWG does not disclose a monthly cost-center ledger.
A4: Code | B4: P&L line | C4: 45658 | D4: 45689 | E4: 45717 | F4: 45748 | G4: 45778 | H4: 45809 | I4: 45839 | J4: 45870 | K4: 45901 | L4: 45931 | M4: 45962 | N4: 45992 | O4: FY2025
A6: ACTUAL | B6: ACTUAL | C6: ACTUAL | D6: ACTUAL | E6: ACTUAL | F6: ACTUAL | G6: ACTUAL | H6: ACTUAL | I6: ACTUAL | J6: ACTUAL | K6: ACTUAL | L6: ACTUAL | M6: ACTUAL | N6: ACTUAL | O6: ACTUAL
A7: REV | B7: Revenue | C7: =SUMIFS('01_Raw_Actual'!$G$6:$G$569,'01_Raw_Actual'!$A$6:$A$569,C$4,'01_Raw_Actual'!$F$6:$F$569,$A7) -> 12276.935 | D7: =SUMIFS('01_Raw_Actual'!$G$6:$G$569,'01_Raw_Actual'!$A$6:$A$569,D$4,'01_Raw_Actual'!$F$6:$F$569,$A7) -> 12276.935 | E7: =SUMIFS('01_Raw_Actual'!$G$6:$G$569,'01_Raw_Actual'!$A$6:$A$569,E$4,'01_Raw_Actual'!$F$6:$F$569,$A7) -> 11581.088 | F7: =SUMIFS('01_Raw_Actual'!$G$6:$G$569,'01_Raw_Actual'!$A$6:$A$569,F$4,'01_Raw_Actual'!$F$6:$F$569,$A7) -> 12562.69 | G7: =SUMIFS('01_Raw_Actual'!$G$6:$G$569,'01_Raw_Actual'!$A$6:$A$569,G$4,'01_Raw_Actual'!$F$6:$F$569,$A7) -> 12612.764 | H7: =SUMIFS('01_Raw_Actual'!$G$6:$G$569,'01_Raw_Actual'!$A$6:$A$569,H$4,'01_Raw_Actual'!$F$6:$F$569,$A7) -> 12444.514 | I7: =SUMIFS('01_Raw_Actual'!$G$6:$G$569,'01_Raw_Actual'!$A$6:$A$569,I$4,'01_Raw_Actual'!$F$6:$F$569,$A7) -> 12875.102 | J7: =SUMIFS('01_Raw_Actual'!$G$6:$G$569,'01_Raw_Actual'!$A$6:$A$569,J$4,'01_Raw_Actual'!$F$6:$F$569,$A7) -> 13317.896 | ... N7: =SUMIFS('01_Raw_Actual'!$G$6:$G$569,'01_Raw_Actual'!$A$6:$A$569,N$4,'01_Raw_Actual'!$F$6:$F$569,$A7) -> 13731.204 | O7: =SUM(C7:N7) -> 155928.15
A8: COGS | B8: COGS | C8: =SUMIFS('01_Raw_Actual'!$G$6:$G$569,'01_Raw_Actual'!$A$6:$A$569,C$4,'01_Raw_Actual'!$F$6:$F$569,$A8) -> -9830.579 | D8: =SUMIFS('01_Raw_Actual'!$G$6:$G$569,'01_Raw_Actual'!$A$6:$A$569,D$4,'01_Raw_Actual'!$F$6:$F$569,$A8) -> -9830.579 | E8: =SUMIFS('01_Raw_Actual'!$G$6:$G$569,'01_Raw_Actual'!$A$6:$A$569,E$4,'01_Raw_Actual'!$F$6:$F$569,$A8) -> -9273.3899 | F8: =SUMIFS('01_Raw_Actual'!$G$6:$G$569,'01_Raw_Actual'!$A$6:$A$569,F$4,'01_Raw_Actual'!$F$6:$F$569,$A8) -> -10035.223 | G8: =SUMIFS('01_Raw_Actual'!$G$6:$G$569,'01_Raw_Actual'!$A$6:$A$569,G$4,'01_Raw_Actual'!$F$6:$F$569,$A8) -> -10075.223 | H8: =SUMIFS('01_Raw_Actual'!$G$6:$G$569,'01_Raw_Actual'!$A$6:$A$569,H$4,'01_Raw_Actual'!$F$6:$F$569,$A8) -> -9940.8225 | I8: =SUMIFS('01_Raw_Actual'!$G$6:$G$569,'01_Raw_Actual'!$A$6:$A$569,I$4,'01_Raw_Actual'!$F$6:$F$569,$A8) -> -10459.133 | J8: =SUMIFS('01_Raw_Actual'!$G$6:$G$569,'01_Raw_Actual'!$A$6:$A$569,J$4,'01_Raw_Actual'!$F$6:$F$569,$A8) -> -10818.838 | ... N8: =SUMIFS('01_Raw_Actual'!$G$6:$G$569,'01_Raw_Actual'!$A$6:$A$569,N$4,'01_Raw_Actual'!$F$6:$F$569,$A8) -> -10890.729 | O8: =SUM(C8:N8) -> -124926.27
B9: Gross Profit | C9: =C7+C8 -> 2446.356 | D9: =D7+D8 -> 2446.356 | E9: =E7+E8 -> 2307.6986 | F9: =F7+F8 -> 2527.4673 | G9: =G7+G8 -> 2537.5417 | H9: =H7+H8 -> 2503.6917 | I9: =I7+I8 -> 2415.9689 | J9: =J7+J8 -> 2499.0578 | ... N9: =N7+N8 -> 2840.4748 | O9: =SUM(C9:N9) -> 31001.877
B10: Gross Margin | C10: =IFERROR(C9/C7,0) -> 0.19926439 | D10: =IFERROR(D9/D7,0) -> 0.19926439 | E10: =IFERROR(E9/E7,0) -> 0.19926439 | F10: =IFERROR(F9/F7,0) -> 0.20118838 | G10: =IFERROR(G9/G7,0) -> 0.20118838 | H10: =IFERROR(H9/H7,0) -> 0.20118838 | I10: =IFERROR(I9/I7,0) -> 0.18764659 | J10: =IFERROR(J9/J7,0) -> 0.18764659 | ... O10: =IFERROR(O9/O7,0) -> 0.19882156
A11: SELL | B11: Selling Expense | C11: =SUMIFS('01_Raw_Actual'!$G$6:$G$569,'01_Raw_Actual'!$A$6:$A$569,C$4,'01_Raw_Actual'!$F$6:$F$569,$A11) -> -1495.9315 | D11: =SUMIFS('01_Raw_Actual'!$G$6:$G$569,'01_Raw_Actual'!$A$6:$A$569,D$4,'01_Raw_Actual'!$F$6:$F$569,$A11) -> -1495.9315 | E11: =SUMIFS('01_Raw_Actual'!$G$6:$G$569,'01_Raw_Actual'!$A$6:$A$569,E$4,'01_Raw_Actual'!$F$6:$F$569,$A11) -> -1411.1433 | F11: =SUMIFS('01_Raw_Actual'!$G$6:$G$569,'01_Raw_Actual'!$A$6:$A$569,F$4,'01_Raw_Actual'!$F$6:$F$569,$A11) -> -1570.5991 | G11: =SUMIFS('01_Raw_Actual'!$G$6:$G$569,'01_Raw_Actual'!$A$6:$A$569,G$4,'01_Raw_Actual'!$F$6:$F$569,$A11) -> -1576.8595 | H11: =SUMIFS('01_Raw_Actual'!$G$6:$G$569,'01_Raw_Actual'!$A$6:$A$569,H$4,'01_Raw_Actual'!$F$6:$F$569,$A11) -> -1555.8246 | I11: =SUMIFS('01_Raw_Actual'!$G$6:$G$569,'01_Raw_Actual'!$A$6:$A$569,I$4,'01_Raw_Actual'!$F$6:$F$569,$A11) -> -1476.6937 | J11: =SUMIFS('01_Raw_Actual'!$G$6:$G$569,'01_Raw_Actual'!$A$6:$A$569,J$4,'01_Raw_Actual'!$F$6:$F$569,$A11) -> -1527.4795 | ... N11: =SUMIFS('01_Raw_Actual'!$G$6:$G$569,'01_Raw_Actual'!$A$6:$A$569,N$4,'01_Raw_Actual'!$F$6:$F$569,$A11) -> -1834.4024 | O11: =SUM(C11:N11) -> -19330.904
A12: GA | B12: G&A | C12: =SUMIFS('01_Raw_Actual'!$G$6:$G$569,'01_Raw_Actual'!$A$6:$A$569,C$4,'01_Raw_Actual'!$F$6:$F$569,$A12) -> -412.66306 | D12: =SUMIFS('01_Raw_Actual'!$G$6:$G$569,'01_Raw_Actual'!$A$6:$A$569,D$4,'01_Raw_Actual'!$F$6:$F$569,$A12) -> -412.66306 | E12: =SUMIFS('01_Raw_Actual'!$G$6:$G$569,'01_Raw_Actual'!$A$6:$A$569,E$4,'01_Raw_Actual'!$F$6:$F$569,$A12) -> -389.27366 | F12: =SUMIFS('01_Raw_Actual'!$G$6:$G$569,'01_Raw_Actual'!$A$6:$A$569,F$4,'01_Raw_Actual'!$F$6:$F$569,$A12) -> -401.28047 | G12: =SUMIFS('01_Raw_Actual'!$G$6:$G$569,'01_Raw_Actual'!$A$6:$A$569,G$4,'01_Raw_Actual'!$F$6:$F$569,$A12) -> -402.87996 | H12: =SUMIFS('01_Raw_Actual'!$G$6:$G$569,'01_Raw_Actual'!$A$6:$A$569,H$4,'01_Raw_Actual'!$F$6:$F$569,$A12) -> -397.50567 | I12: =SUMIFS('01_Raw_Actual'!$G$6:$G$569,'01_Raw_Actual'!$A$6:$A$569,I$4,'01_Raw_Actual'!$F$6:$F$569,$A12) -> -361.64782 | J12: =SUMIFS('01_Raw_Actual'!$G$6:$G$569,'01_Raw_Actual'!$A$6:$A$569,J$4,'01_Raw_Actual'!$F$6:$F$569,$A12) -> -374.08545 | ... N12: =SUMIFS('01_Raw_Actual'!$G$6:$G$569,'01_Raw_Actual'!$A$6:$A$569,N$4,'01_Raw_Actual'!$F$6:$F$569,$A12) -> -344.05119 | O12: =SUM(C12:N12) -> -4596.0745
B13: Operating Profit | C13: =SUM(C9,C11:C12) -> 537.76145 | D13: =SUM(D9,D11:D12) -> 537.76145 | E13: =SUM(E9,E11:E12) -> 507.28158 | F13: =SUM(F9,F11:F12) -> 555.58772 | G13: =SUM(G9,G11:G12) -> 557.80227 | H13: =SUM(H9,H11:H12) -> 550.36137 | I13: =SUM(I9,I11:I12) -> 577.62735 | J13: =SUM(J9,J11:J12) -> 597.49284 | ... N13: =SUM(N9,N11:N12) -> 662.02121 | O13: =SUM(C13:N13) -> 7074.8993
A14: FIN_INC | B14: Finance Income | C14: =SUMIFS('01_Raw_Actual'!$G$6:$G$569,'01_Raw_Actual'!$A$6:$A$569,C$4,'01_Raw_Actual'!$F$6:$F$569,$A14) -> 235.54811 | D14: =SUMIFS('01_Raw_Actual'!$G$6:$G$569,'01_Raw_Actual'!$A$6:$A$569,D$4,'01_Raw_Actual'!$F$6:$F$569,$A14) -> 235.54811 | E14: =SUMIFS('01_Raw_Actual'!$G$6:$G$569,'01_Raw_Actual'!$A$6:$A$569,E$4,'01_Raw_Actual'!$F$6:$F$569,$A14) -> 222.19744 | F14: =SUMIFS('01_Raw_Actual'!$G$6:$G$569,'01_Raw_Actual'!$A$6:$A$569,F$4,'01_Raw_Actual'!$F$6:$F$569,$A14) -> 256.74134 | G14: =SUMIFS('01_Raw_Actual'!$G$6:$G$569,'01_Raw_Actual'!$A$6:$A$569,G$4,'01_Raw_Actual'!$F$6:$F$569,$A14) -> 257.7647 | H14: =SUMIFS('01_Raw_Actual'!$G$6:$G$569,'01_Raw_Actual'!$A$6:$A$569,H$4,'01_Raw_Actual'!$F$6:$F$569,$A14) -> 254.3262 | I14: =SUMIFS('01_Raw_Actual'!$G$6:$G$569,'01_Raw_Actual'!$A$6:$A$569,I$4,'01_Raw_Actual'!$F$6:$F$569,$A14) -> 261.38492 | J14: =SUMIFS('01_Raw_Actual'!$G$6:$G$569,'01_Raw_Actual'!$A$6:$A$569,J$4,'01_Raw_Actual'!$F$6:$F$569,$A14) -> 270.37435 | ... N14: =SUMIFS('01_Raw_Actual'!$G$6:$G$569,'01_Raw_Actual'!$A$6:$A$569,N$4,'01_Raw_Actual'!$F$6:$F$569,$A14) -> 271.29506 | O14: =SUM(C14:N14) -> 3107.3487
A15: FIN_EXP | B15: Finance Expense | C15: =SUMIFS('01_Raw_Actual'!$G$6:$G$569,'01_Raw_Actual'!$A$6:$A$569,C$4,'01_Raw_Actual'!$F$6:$F$569,$A15) -> -115.1839 | D15: =SUMIFS('01_Raw_Actual'!$G$6:$G$569,'01_Raw_Actual'!$A$6:$A$569,D$4,'01_Raw_Actual'!$F$6:$F$569,$A15) -> -115.1839 | E15: =SUMIFS('01_Raw_Actual'!$G$6:$G$569,'01_Raw_Actual'!$A$6:$A$569,E$4,'01_Raw_Actual'!$F$6:$F$569,$A15) -> -108.65537 | F15: =SUMIFS('01_Raw_Actual'!$G$6:$G$569,'01_Raw_Actual'!$A$6:$A$569,F$4,'01_Raw_Actual'!$F$6:$F$569,$A15) -> -134.39434 | G15: =SUMIFS('01_Raw_Actual'!$G$6:$G$569,'01_Raw_Actual'!$A$6:$A$569,G$4,'01_Raw_Actual'!$F$6:$F$569,$A15) -> -134.93003 | H15: =SUMIFS('01_Raw_Actual'!$G$6:$G$569,'01_Raw_Actual'!$A$6:$A$569,H$4,'01_Raw_Actual'!$F$6:$F$569,$A15) -> -133.1301 | I15: =SUMIFS('01_Raw_Actual'!$G$6:$G$569,'01_Raw_Actual'!$A$6:$A$569,I$4,'01_Raw_Actual'!$F$6:$F$569,$A15) -> -132.69834 | J15: =SUMIFS('01_Raw_Actual'!$G$6:$G$569,'01_Raw_Actual'!$A$6:$A$569,J$4,'01_Raw_Actual'!$F$6:$F$569,$A15) -> -137.26204 | ... N15: =SUMIFS('01_Raw_Actual'!$G$6:$G$569,'01_Raw_Actual'!$A$6:$A$569,N$4,'01_Raw_Actual'!$F$6:$F$569,$A15) -> -126.63441 | O15: =SUM(C15:N15) -> -1542.5187
A16: JV | B16: JV Profit/(Loss) | C16: =SUMIFS('01_Raw_Actual'!$G$6:$G$569,'01_Raw_Actual'!$A$6:$A$569,C$4,'01_Raw_Actual'!$F$6:$F$569,$A16) -> 1.063348 | D16: =SUMIFS('01_Raw_Actual'!$G$6:$G$569,'01_Raw_Actual'!$A$6:$A$569,D$4,'01_Raw_Actual'!$F$6:$F$569,$A16) -> 1.063348 | E16: =SUMIFS('01_Raw_Actual'!$G$6:$G$569,'01_Raw_Actual'!$A$6:$A$569,E$4,'01_Raw_Actual'!$F$6:$F$569,$A16) -> 1.0030783 | F16: =SUMIFS('01_Raw_Actual'!$G$6:$G$569,'01_Raw_Actual'!$A$6:$A$569,F$4,'01_Raw_Actual'!$F$6:$F$569,$A16) -> 3.7139212 | G16: =SUMIFS('01_Raw_Actual'!$G$6:$G$569,'01_Raw_Actual'!$A$6:$A$569,G$4,'01_Raw_Actual'!$F$6:$F$569,$A16) -> 3.7287248 | H16: =SUMIFS('01_Raw_Actual'!$G$6:$G$569,'01_Raw_Actual'!$A$6:$A$569,H$4,'01_Raw_Actual'!$F$6:$F$569,$A16) -> 3.6789848 | I16: =SUMIFS('01_Raw_Actual'!$G$6:$G$569,'01_Raw_Actual'!$A$6:$A$569,I$4,'01_Raw_Actual'!$F$6:$F$569,$A16) -> 1.3493619 | J16: =SUMIFS('01_Raw_Actual'!$G$6:$G$569,'01_Raw_Actual'!$A$6:$A$569,J$4,'01_Raw_Actual'!$F$6:$F$569,$A16) -> 1.3957685 | ... N16: =SUMIFS('01_Raw_Actual'!$G$6:$G$569,'01_Raw_Actual'!$A$6:$A$569,N$4,'01_Raw_Actual'!$F$6:$F$569,$A16) -> 1.9217434 | O16: =SUM(C16:N16) -> 24.351079
A17: OTHER | B17: Other Net | C17: =SUMIFS('01_Raw_Actual'!$G$6:$G$569,'01_Raw_Actual'!$A$6:$A$569,C$4,'01_Raw_Actual'!$F$6:$F$569,$A17) -> -1.8833751 | D17: =SUMIFS('01_Raw_Actual'!$G$6:$G$569,'01_Raw_Actual'!$A$6:$A$569,D$4,'01_Raw_Actual'!$F$6:$F$569,$A17) -> -1.8833751 | E17: =SUMIFS('01_Raw_Actual'!$G$6:$G$569,'01_Raw_Actual'!$A$6:$A$569,E$4,'01_Raw_Actual'!$F$6:$F$569,$A17) -> -1.776627 | F17: =SUMIFS('01_Raw_Actual'!$G$6:$G$569,'01_Raw_Actual'!$A$6:$A$569,F$4,'01_Raw_Actual'!$F$6:$F$569,$A17) -> -4.3565437 | G17: =SUMIFS('01_Raw_Actual'!$G$6:$G$569,'01_Raw_Actual'!$A$6:$A$569,G$4,'01_Raw_Actual'!$F$6:$F$569,$A17) -> -4.3739087 | H17: =SUMIFS('01_Raw_Actual'!$G$6:$G$569,'01_Raw_Actual'!$A$6:$A$569,H$4,'01_Raw_Actual'!$F$6:$F$569,$A17) -> -4.3155622 | I17: =SUMIFS('01_Raw_Actual'!$G$6:$G$569,'01_Raw_Actual'!$A$6:$A$569,I$4,'01_Raw_Actual'!$F$6:$F$569,$A17) -> -5.8444054 | J17: =SUMIFS('01_Raw_Actual'!$G$6:$G$569,'01_Raw_Actual'!$A$6:$A$569,J$4,'01_Raw_Actual'!$F$6:$F$569,$A17) -> -6.0454035 | ... N17: =SUMIFS('01_Raw_Actual'!$G$6:$G$569,'01_Raw_Actual'!$A$6:$A$569,N$4,'01_Raw_Actual'!$F$6:$F$569,$A17) -> 1.8386158 | O17: =SUM(C17:N17) -> -31.012906
B18: Profit Before Tax | C18: =SUM(C13:C17) -> 657.30564 | D18: =SUM(D13:D17) -> 657.30564 | E18: =SUM(E13:E17) -> 620.0501 | F18: =SUM(F13:F17) -> 677.2921 | G18: =SUM(G13:G17) -> 679.99177 | H18: =SUM(H13:H17) -> 670.92089 | I18: =SUM(I13:I17) -> 701.81889 | J18: =SUM(J13:J17) -> 725.95552 | ... N18: =SUM(N13:N17) -> 810.44222 | O18: =SUM(C18:N18) -> 8633.0676
A19: TAX | B19: Tax Expense | C19: =SUMIFS('01_Raw_Actual'!$G$6:$G$569,'01_Raw_Actual'!$A$6:$A$569,C$4,'01_Raw_Actual'!$F$6:$F$569,$A19) -> -131.42557 | D19: =SUMIFS('01_Raw_Actual'!$G$6:$G$569,'01_Raw_Actual'!$A$6:$A$569,D$4,'01_Raw_Actual'!$F$6:$F$569,$A19) -> -131.42557 | E19: =SUMIFS('01_Raw_Actual'!$G$6:$G$569,'01_Raw_Actual'!$A$6:$A$569,E$4,'01_Raw_Actual'!$F$6:$F$569,$A19) -> -123.97648 | F19: =SUMIFS('01_Raw_Actual'!$G$6:$G$569,'01_Raw_Actual'!$A$6:$A$569,F$4,'01_Raw_Actual'!$F$6:$F$569,$A19) -> -123.78222 | G19: =SUMIFS('01_Raw_Actual'!$G$6:$G$569,'01_Raw_Actual'!$A$6:$A$569,G$4,'01_Raw_Actual'!$F$6:$F$569,$A19) -> -124.27561 | H19: =SUMIFS('01_Raw_Actual'!$G$6:$G$569,'01_Raw_Actual'!$A$6:$A$569,H$4,'01_Raw_Actual'!$F$6:$F$569,$A19) -> -122.61781 | I19: =SUMIFS('01_Raw_Actual'!$G$6:$G$569,'01_Raw_Actual'!$A$6:$A$569,I$4,'01_Raw_Actual'!$F$6:$F$569,$A19) -> -125.57217 | J19: =SUMIFS('01_Raw_Actual'!$G$6:$G$569,'01_Raw_Actual'!$A$6:$A$569,J$4,'01_Raw_Actual'!$F$6:$F$569,$A19) -> -129.89079 | ... N19: =SUMIFS('01_Raw_Actual'!$G$6:$G$569,'01_Raw_Actual'!$A$6:$A$569,N$4,'01_Raw_Actual'!$F$6:$F$569,$A19) -> -134.40777 | O19: =SUM(C19:N19) -> -1560.4447
B20: PAT | C20: =C18+C19 -> 525.88007 | D20: =D18+D19 -> 525.88007 | E20: =E18+E19 -> 496.07363 | F20: =F18+F19 -> 553.50988 | G20: =G18+G19 -> 555.71616 | H20: =H18+H19 -> 548.30308 | I20: =I18+I19 -> 576.24672 | J20: =J18+J19 -> 596.06473 | ... N20: =N18+N19 -> 676.03445 | O20: =SUM(C20:N20) -> 7072.6229
A23: BUDGET | B23: BUDGET | C23: BUDGET | D23: BUDGET | E23: BUDGET | F23: BUDGET | G23: BUDGET | H23: BUDGET | I23: BUDGET | J23: BUDGET | K23: BUDGET | L23: BUDGET | M23: BUDGET | N23: BUDGET | O23: BUDGET
A24: REV | B24: Revenue | C24: =SUMIFS('02_Raw_Budget'!$G$6:$G$869,'02_Raw_Budget'!$A$6:$A$869,C$4,'02_Raw_Budget'!$F$6:$F$869,$A24) -> 12066.123 | D24: =SUMIFS('02_Raw_Budget'!$G$6:$G$869,'02_Raw_Budget'!$A$6:$A$869,D$4,'02_Raw_Budget'!$F$6:$F$869,$A24) -> 12066.123 | E24: =SUMIFS('02_Raw_Budget'!$G$6:$G$869,'02_Raw_Budget'!$A$6:$A$869,E$4,'02_Raw_Budget'!$F$6:$F$869,$A24) -> 10973.567 | F24: =SUMIFS('02_Raw_Budget'!$G$6:$G$869,'02_Raw_Budget'!$A$6:$A$869,F$4,'02_Raw_Budget'!$F$6:$F$869,$A24) -> 12949.881 | G24: =SUMIFS('02_Raw_Budget'!$G$6:$G$869,'02_Raw_Budget'!$A$6:$A$869,G$4,'02_Raw_Budget'!$F$6:$F$869,$A24) -> 12506.606 | H24: =SUMIFS('02_Raw_Budget'!$G$6:$G$869,'02_Raw_Budget'!$A$6:$A$869,H$4,'02_Raw_Budget'!$F$6:$F$869,$A24) -> 12707.587 | I24: =SUMIFS('02_Raw_Budget'!$G$6:$G$869,'02_Raw_Budget'!$A$6:$A$869,I$4,'02_Raw_Budget'!$F$6:$F$869,$A24) -> 12192.853 | J24: =SUMIFS('02_Raw_Budget'!$G$6:$G$869,'02_Raw_Budget'!$A$6:$A$869,J$4,'02_Raw_Budget'!$F$6:$F$869,$A24) -> 12757.833 | ... N24: =SUMIFS('02_Raw_Budget'!$G$6:$G$869,'02_Raw_Budget'!$A$6:$A$869,N$4,'02_Raw_Budget'!$F$6:$F$869,$A24) -> 13446.751 | O24: =SUM(C24:N24) -> 150000
A25: COGS | B25: COGS | C25: =SUMIFS('02_Raw_Budget'!$G$6:$G$869,'02_Raw_Budget'!$A$6:$A$869,C$4,'02_Raw_Budget'!$F$6:$F$869,$A25) -> -9604.4326 | D25: =SUMIFS('02_Raw_Budget'!$G$6:$G$869,'02_Raw_Budget'!$A$6:$A$869,D$4,'02_Raw_Budget'!$F$6:$F$869,$A25) -> -9604.4326 | E25: =SUMIFS('02_Raw_Budget'!$G$6:$G$869,'02_Raw_Budget'!$A$6:$A$869,E$4,'02_Raw_Budget'!$F$6:$F$869,$A25) -> -8734.7767 | F25: =SUMIFS('02_Raw_Budget'!$G$6:$G$869,'02_Raw_Budget'!$A$6:$A$869,F$4,'02_Raw_Budget'!$F$6:$F$869,$A25) -> -10307.89 | G25: =SUMIFS('02_Raw_Budget'!$G$6:$G$869,'02_Raw_Budget'!$A$6:$A$869,G$4,'02_Raw_Budget'!$F$6:$F$869,$A25) -> -9955.0502 | H25: =SUMIFS('02_Raw_Budget'!$G$6:$G$869,'02_Raw_Budget'!$A$6:$A$869,H$4,'02_Raw_Budget'!$F$6:$F$869,$A25) -> -10115.028 | I25: =SUMIFS('02_Raw_Budget'!$G$6:$G$869,'02_Raw_Budget'!$A$6:$A$869,I$4,'02_Raw_Budget'!$F$6:$F$869,$A25) -> -9705.3074 | J25: =SUMIFS('02_Raw_Budget'!$G$6:$G$869,'02_Raw_Budget'!$A$6:$A$869,J$4,'02_Raw_Budget'!$F$6:$F$869,$A25) -> -10155.022 | ... N25: =SUMIFS('02_Raw_Budget'!$G$6:$G$869,'02_Raw_Budget'!$A$6:$A$869,N$4,'02_Raw_Budget'!$F$6:$F$869,$A25) -> -10703.39 | O25: =SUM(C25:N25) -> -119397.5
B26: Gross Profit | C26: =C24+C25 -> 2461.6901 | D26: =D24+D25 -> 2461.6901 | E26: =E24+E25 -> 2238.7906 | F26: =F24+F25 -> 2641.9916 | G26: =G24+G25 -> 2551.5561 | H26: =H24+H25 -> 2592.5596 | I26: =I24+I25 -> 2487.5451 | J26: =J24+J25 -> 2602.8105 | ... N26: =N24+N25 -> 2743.3614 | O26: =SUM(C26:N26) -> 30602.5
B27: Gross Margin | C27: =IFERROR(C26/C24,0) -> 0.20401667 | D27: =IFERROR(D26/D24,0) -> 0.20401667 | E27: =IFERROR(E26/E24,0) -> 0.20401667 | F27: =IFERROR(F26/F24,0) -> 0.20401667 | G27: =IFERROR(G26/G24,0) -> 0.20401667 | H27: =IFERROR(H26/H24,0) -> 0.20401667 | I27: =IFERROR(I26/I24,0) -> 0.20401667 | J27: =IFERROR(J26/J24,0) -> 0.20401667 | ... O27: =IFERROR(O26/O24,0) -> 0.20401667
A28: SELL | B28: Selling Expense | C28: =SUMIFS('02_Raw_Budget'!$G$6:$G$869,'02_Raw_Budget'!$A$6:$A$869,C$4,'02_Raw_Budget'!$F$6:$F$869,$A28) -> -1713.3894 | D28: =SUMIFS('02_Raw_Budget'!$G$6:$G$869,'02_Raw_Budget'!$A$6:$A$869,D$4,'02_Raw_Budget'!$F$6:$F$869,$A28) -> -1713.3894 | E28: =SUMIFS('02_Raw_Budget'!$G$6:$G$869,'02_Raw_Budget'!$A$6:$A$869,E$4,'02_Raw_Budget'!$F$6:$F$869,$A28) -> -1558.2466 | F28: =SUMIFS('02_Raw_Budget'!$G$6:$G$869,'02_Raw_Budget'!$A$6:$A$869,F$4,'02_Raw_Budget'!$F$6:$F$869,$A28) -> -1838.8831 | G28: =SUMIFS('02_Raw_Budget'!$G$6:$G$869,'02_Raw_Budget'!$A$6:$A$869,G$4,'02_Raw_Budget'!$F$6:$F$869,$A28) -> -1775.9381 | H28: =SUMIFS('02_Raw_Budget'!$G$6:$G$869,'02_Raw_Budget'!$A$6:$A$869,H$4,'02_Raw_Budget'!$F$6:$F$869,$A28) -> -1804.4774 | I28: =SUMIFS('02_Raw_Budget'!$G$6:$G$869,'02_Raw_Budget'!$A$6:$A$869,I$4,'02_Raw_Budget'!$F$6:$F$869,$A28) -> -1731.3851 | J28: =SUMIFS('02_Raw_Budget'!$G$6:$G$869,'02_Raw_Budget'!$A$6:$A$869,J$4,'02_Raw_Budget'!$F$6:$F$869,$A28) -> -1811.6122 | ... N28: =SUMIFS('02_Raw_Budget'!$G$6:$G$869,'02_Raw_Budget'!$A$6:$A$869,N$4,'02_Raw_Budget'!$F$6:$F$869,$A28) -> -1909.4387 | O28: =SUM(C28:N28) -> -21300
A29: GA | B29: G&A | C29: =SUMIFS('02_Raw_Budget'!$G$6:$G$869,'02_Raw_Budget'!$A$6:$A$869,C$4,'02_Raw_Budget'!$F$6:$F$869,$A29) -> -325.78531 | D29: =SUMIFS('02_Raw_Budget'!$G$6:$G$869,'02_Raw_Budget'!$A$6:$A$869,D$4,'02_Raw_Budget'!$F$6:$F$869,$A29) -> -325.78531 | E29: =SUMIFS('02_Raw_Budget'!$G$6:$G$869,'02_Raw_Budget'!$A$6:$A$869,E$4,'02_Raw_Budget'!$F$6:$F$869,$A29) -> -296.28632 | F29: =SUMIFS('02_Raw_Budget'!$G$6:$G$869,'02_Raw_Budget'!$A$6:$A$869,F$4,'02_Raw_Budget'!$F$6:$F$869,$A29) -> -349.64679 | G29: =SUMIFS('02_Raw_Budget'!$G$6:$G$869,'02_Raw_Budget'!$A$6:$A$869,G$4,'02_Raw_Budget'!$F$6:$F$869,$A29) -> -337.67837 | H29: =SUMIFS('02_Raw_Budget'!$G$6:$G$869,'02_Raw_Budget'!$A$6:$A$869,H$4,'02_Raw_Budget'!$F$6:$F$869,$A29) -> -343.10486 | I29: =SUMIFS('02_Raw_Budget'!$G$6:$G$869,'02_Raw_Budget'!$A$6:$A$869,I$4,'02_Raw_Budget'!$F$6:$F$869,$A29) -> -329.20702 | J29: =SUMIFS('02_Raw_Budget'!$G$6:$G$869,'02_Raw_Budget'!$A$6:$A$869,J$4,'02_Raw_Budget'!$F$6:$F$869,$A29) -> -344.46148 | ... N29: =SUMIFS('02_Raw_Budget'!$G$6:$G$869,'02_Raw_Budget'!$A$6:$A$869,N$4,'02_Raw_Budget'!$F$6:$F$869,$A29) -> -363.06228 | O29: =SUM(C29:N29) -> -4050
B30: Operating Profit | C30: =SUM(C26,C28:C29) -> 422.5154 | D30: =SUM(D26,D28:D29) -> 422.5154 | E30: =SUM(E26,E28:E29) -> 384.25775 | F30: =SUM(F26,F28:F29) -> 453.46168 | G30: =SUM(G26,G28:G29) -> 437.93966 | H30: =SUM(H26,H28:H29) -> 444.97735 | I30: =SUM(I26,I28:I29) -> 426.95305 | J30: =SUM(J26,J28:J29) -> 446.73677 | ... N30: =SUM(N26,N28:N29) -> 470.8604 | O30: =SUM(C30:N30) -> 5252.5
A31: FIN_INC | B31: Finance Income | C31: =SUMIFS('02_Raw_Budget'!$G$6:$G$869,'02_Raw_Budget'!$A$6:$A$869,C$4,'02_Raw_Budget'!$F$6:$F$869,$A31) -> 180.99184 | D31: =SUMIFS('02_Raw_Budget'!$G$6:$G$869,'02_Raw_Budget'!$A$6:$A$869,D$4,'02_Raw_Budget'!$F$6:$F$869,$A31) -> 180.99184 | E31: =SUMIFS('02_Raw_Budget'!$G$6:$G$869,'02_Raw_Budget'!$A$6:$A$869,E$4,'02_Raw_Budget'!$F$6:$F$869,$A31) -> 164.60351 | F31: =SUMIFS('02_Raw_Budget'!$G$6:$G$869,'02_Raw_Budget'!$A$6:$A$869,F$4,'02_Raw_Budget'!$F$6:$F$869,$A31) -> 194.24822 | G31: =SUMIFS('02_Raw_Budget'!$G$6:$G$869,'02_Raw_Budget'!$A$6:$A$869,G$4,'02_Raw_Budget'!$F$6:$F$869,$A31) -> 187.59909 | H31: =SUMIFS('02_Raw_Budget'!$G$6:$G$869,'02_Raw_Budget'!$A$6:$A$869,H$4,'02_Raw_Budget'!$F$6:$F$869,$A31) -> 190.61381 | I31: =SUMIFS('02_Raw_Budget'!$G$6:$G$869,'02_Raw_Budget'!$A$6:$A$869,I$4,'02_Raw_Budget'!$F$6:$F$869,$A31) -> 182.89279 | J31: =SUMIFS('02_Raw_Budget'!$G$6:$G$869,'02_Raw_Budget'!$A$6:$A$869,J$4,'02_Raw_Budget'!$F$6:$F$869,$A31) -> 191.36749 | ... N31: =SUMIFS('02_Raw_Budget'!$G$6:$G$869,'02_Raw_Budget'!$A$6:$A$869,N$4,'02_Raw_Budget'!$F$6:$F$869,$A31) -> 201.70127 | O31: =SUM(C31:N31) -> 2250
A32: FIN_EXP | B32: Finance Expense | C32: =SUMIFS('02_Raw_Budget'!$G$6:$G$869,'02_Raw_Budget'!$A$6:$A$869,C$4,'02_Raw_Budget'!$F$6:$F$869,$A32) -> -96.528982 | D32: =SUMIFS('02_Raw_Budget'!$G$6:$G$869,'02_Raw_Budget'!$A$6:$A$869,D$4,'02_Raw_Budget'!$F$6:$F$869,$A32) -> -96.528982 | E32: =SUMIFS('02_Raw_Budget'!$G$6:$G$869,'02_Raw_Budget'!$A$6:$A$869,E$4,'02_Raw_Budget'!$F$6:$F$869,$A32) -> -87.788538 | F32: =SUMIFS('02_Raw_Budget'!$G$6:$G$869,'02_Raw_Budget'!$A$6:$A$869,F$4,'02_Raw_Budget'!$F$6:$F$869,$A32) -> -103.59905 | G32: =SUMIFS('02_Raw_Budget'!$G$6:$G$869,'02_Raw_Budget'!$A$6:$A$869,G$4,'02_Raw_Budget'!$F$6:$F$869,$A32) -> -100.05285 | H32: =SUMIFS('02_Raw_Budget'!$G$6:$G$869,'02_Raw_Budget'!$A$6:$A$869,H$4,'02_Raw_Budget'!$F$6:$F$869,$A32) -> -101.6607 | I32: =SUMIFS('02_Raw_Budget'!$G$6:$G$869,'02_Raw_Budget'!$A$6:$A$869,I$4,'02_Raw_Budget'!$F$6:$F$869,$A32) -> -97.54282 | J32: =SUMIFS('02_Raw_Budget'!$G$6:$G$869,'02_Raw_Budget'!$A$6:$A$869,J$4,'02_Raw_Budget'!$F$6:$F$869,$A32) -> -102.06266 | ... N32: =SUMIFS('02_Raw_Budget'!$G$6:$G$869,'02_Raw_Budget'!$A$6:$A$869,N$4,'02_Raw_Budget'!$F$6:$F$869,$A32) -> -107.57401 | O32: =SUM(C32:N32) -> -1200
A33: JV | B33: JV Profit/(Loss) | C33: =SUMIFS('02_Raw_Budget'!$G$6:$G$869,'02_Raw_Budget'!$A$6:$A$869,C$4,'02_Raw_Budget'!$F$6:$F$869,$A33) -> 0 | D33: =SUMIFS('02_Raw_Budget'!$G$6:$G$869,'02_Raw_Budget'!$A$6:$A$869,D$4,'02_Raw_Budget'!$F$6:$F$869,$A33) -> 0 | E33: =SUMIFS('02_Raw_Budget'!$G$6:$G$869,'02_Raw_Budget'!$A$6:$A$869,E$4,'02_Raw_Budget'!$F$6:$F$869,$A33) -> 0 | F33: =SUMIFS('02_Raw_Budget'!$G$6:$G$869,'02_Raw_Budget'!$A$6:$A$869,F$4,'02_Raw_Budget'!$F$6:$F$869,$A33) -> 0 | G33: =SUMIFS('02_Raw_Budget'!$G$6:$G$869,'02_Raw_Budget'!$A$6:$A$869,G$4,'02_Raw_Budget'!$F$6:$F$869,$A33) -> 0 | H33: =SUMIFS('02_Raw_Budget'!$G$6:$G$869,'02_Raw_Budget'!$A$6:$A$869,H$4,'02_Raw_Budget'!$F$6:$F$869,$A33) -> 0 | I33: =SUMIFS('02_Raw_Budget'!$G$6:$G$869,'02_Raw_Budget'!$A$6:$A$869,I$4,'02_Raw_Budget'!$F$6:$F$869,$A33) -> 0 | J33: =SUMIFS('02_Raw_Budget'!$G$6:$G$869,'02_Raw_Budget'!$A$6:$A$869,J$4,'02_Raw_Budget'!$F$6:$F$869,$A33) -> 0 | ... N33: =SUMIFS('02_Raw_Budget'!$G$6:$G$869,'02_Raw_Budget'!$A$6:$A$869,N$4,'02_Raw_Budget'!$F$6:$F$869,$A33) -> 0 | O33: =SUM(C33:N33) -> 0
A34: OTHER | B34: Other Net | C34: =SUMIFS('02_Raw_Budget'!$G$6:$G$869,'02_Raw_Budget'!$A$6:$A$869,C$4,'02_Raw_Budget'!$F$6:$F$869,$A34) -> -19.305796 | D34: =SUMIFS('02_Raw_Budget'!$G$6:$G$869,'02_Raw_Budget'!$A$6:$A$869,D$4,'02_Raw_Budget'!$F$6:$F$869,$A34) -> -19.305796 | E34: =SUMIFS('02_Raw_Budget'!$G$6:$G$869,'02_Raw_Budget'!$A$6:$A$869,E$4,'02_Raw_Budget'!$F$6:$F$869,$A34) -> -17.557708 | F34: =SUMIFS('02_Raw_Budget'!$G$6:$G$869,'02_Raw_Budget'!$A$6:$A$869,F$4,'02_Raw_Budget'!$F$6:$F$869,$A34) -> -20.71981 | G34: =SUMIFS('02_Raw_Budget'!$G$6:$G$869,'02_Raw_Budget'!$A$6:$A$869,G$4,'02_Raw_Budget'!$F$6:$F$869,$A34) -> -20.01057 | H34: =SUMIFS('02_Raw_Budget'!$G$6:$G$869,'02_Raw_Budget'!$A$6:$A$869,H$4,'02_Raw_Budget'!$F$6:$F$869,$A34) -> -20.33214 | I34: =SUMIFS('02_Raw_Budget'!$G$6:$G$869,'02_Raw_Budget'!$A$6:$A$869,I$4,'02_Raw_Budget'!$F$6:$F$869,$A34) -> -19.508564 | J34: =SUMIFS('02_Raw_Budget'!$G$6:$G$869,'02_Raw_Budget'!$A$6:$A$869,J$4,'02_Raw_Budget'!$F$6:$F$869,$A34) -> -20.412532 | ... N34: =SUMIFS('02_Raw_Budget'!$G$6:$G$869,'02_Raw_Budget'!$A$6:$A$869,N$4,'02_Raw_Budget'!$F$6:$F$869,$A34) -> -21.514802 | O34: =SUM(C34:N34) -> -240
B35: Profit Before Tax | C35: =SUM(C30:C34) -> 487.67246 | D35: =SUM(D30:D34) -> 487.67246 | E35: =SUM(E30:E34) -> 443.51501 | F35: =SUM(F30:F34) -> 523.39103 | G35: =SUM(G30:G34) -> 505.47534 | H35: =SUM(H30:H34) -> 513.59832 | I35: =SUM(I30:I34) -> 492.79446 | J35: =SUM(J30:J34) -> 515.62907 | ... N35: =SUM(N30:N34) -> 543.47286 | O35: =SUM(C35:N35) -> 6062.5
A36: TAX | B36: Tax Expense | C36: =SUMIFS('02_Raw_Budget'!$G$6:$G$869,'02_Raw_Budget'!$A$6:$A$869,C$4,'02_Raw_Budget'!$F$6:$F$869,$A36) -> -97.534492 | D36: =SUMIFS('02_Raw_Budget'!$G$6:$G$869,'02_Raw_Budget'!$A$6:$A$869,D$4,'02_Raw_Budget'!$F$6:$F$869,$A36) -> -97.534492 | E36: =SUMIFS('02_Raw_Budget'!$G$6:$G$869,'02_Raw_Budget'!$A$6:$A$869,E$4,'02_Raw_Budget'!$F$6:$F$869,$A36) -> -88.703002 | F36: =SUMIFS('02_Raw_Budget'!$G$6:$G$869,'02_Raw_Budget'!$A$6:$A$869,F$4,'02_Raw_Budget'!$F$6:$F$869,$A36) -> -104.67821 | G36: =SUMIFS('02_Raw_Budget'!$G$6:$G$869,'02_Raw_Budget'!$A$6:$A$869,G$4,'02_Raw_Budget'!$F$6:$F$869,$A36) -> -101.09507 | H36: =SUMIFS('02_Raw_Budget'!$G$6:$G$869,'02_Raw_Budget'!$A$6:$A$869,H$4,'02_Raw_Budget'!$F$6:$F$869,$A36) -> -102.71966 | I36: =SUMIFS('02_Raw_Budget'!$G$6:$G$869,'02_Raw_Budget'!$A$6:$A$869,I$4,'02_Raw_Budget'!$F$6:$F$869,$A36) -> -98.558891 | J36: =SUMIFS('02_Raw_Budget'!$G$6:$G$869,'02_Raw_Budget'!$A$6:$A$869,J$4,'02_Raw_Budget'!$F$6:$F$869,$A36) -> -103.12581 | ... N36: =SUMIFS('02_Raw_Budget'!$G$6:$G$869,'02_Raw_Budget'!$A$6:$A$869,N$4,'02_Raw_Budget'!$F$6:$F$869,$A36) -> -108.69457 | O36: =SUM(C36:N36) -> -1212.5
B37: PAT | C37: =C35+C36 -> 390.13797 | D37: =D35+D36 -> 390.13797 | E37: =E35+E36 -> 354.81201 | F37: =F35+F36 -> 418.71283 | G37: =G35+G36 -> 404.38027 | H37: =H35+H36 -> 410.87866 | I37: =I35+I36 -> 394.23556 | J37: =J35+J36 -> 412.50326 | ... N37: =N35+N36 -> 434.77829 | O37: =SUM(C37:N37) -> 4850
A40: VARIANCE — ACTUAL MINUS BUDGET | B40: VARIANCE — ACTUAL MINUS BUDGET | C40: VARIANCE — ACTUAL MINUS BUDGET | D40: VARIANCE — ACTUAL MINUS BUDGET | E40: VARIANCE — ACTUAL MINUS BUDGET | F40: VARIANCE — ACTUAL MINUS BUDGET | G40: VARIANCE — ACTUAL MINUS BUDGET | H40: VARIANCE — ACTUAL MINUS BUDGET | I40: VARIANCE — ACTUAL MINUS BUDGET | J40: VARIANCE — ACTUAL MINUS BUDGET | K40: VARIANCE — ACTUAL MINUS BUDGET | L40: VARIANCE — ACTUAL MINUS BUDGET | M40: VARIANCE — ACTUAL MINUS BUDGET | N40: VARIANCE — ACTUAL MINUS BUDGET | O40: VARIANCE — ACTUAL MINUS BUDGET
A41: REV | B41: Revenue | C41: =C7-C24 -> 210.8122 | D41: =D7-D24 -> 210.8122 | E41: =E7-E24 -> 607.52121 | F41: =F7-F24 -> -387.19128 | G41: =G7-G24 -> 106.15817 | H41: =H7-H24 -> -263.07323 | I41: =I7-I24 -> 682.24921 | J41: =J7-J24 -> 560.06355 | ... O41: =O7-O24 -> 5928.1456
A42: COGS | B42: COGS | C42: =C8-C25 -> -226.14633 | D42: =D8-D25 -> -226.14633 | E42: =E8-E25 -> -538.61324 | F42: =F8-F25 -> 272.66695 | G42: =G8-G25 -> -120.17261 | H42: =H8-H25 -> 174.20529 | I42: =I8-I25 -> -753.82547 | J42: =J8-J25 -> -663.8163 | ... O42: =O8-O25 -> -5528.7682
B43: Gross Profit | C43: =C9-C26 -> -15.334133 | D43: =D9-D26 -> -15.334133 | E43: =E9-E26 -> 68.907969 | F43: =F9-F26 -> -114.52433 | G43: =G9-G26 -> -14.014441 | H43: =H9-H26 -> -88.867941 | I43: =I9-I26 -> -71.576254 | J43: =J9-J26 -> -103.75275 | ... O43: =O9-O26 -> 399.3774
B44: Gross Margin | C44: =C10-C27 -> -0.004752272 | D44: =D10-D27 -> -0.004752272 | E44: =E10-E27 -> -0.004752272 | F44: =F10-F27 -> -0.0028282837 | G44: =G10-G27 -> -0.0028282837 | H44: =H10-H27 -> -0.0028282837 | I44: =I10-I27 -> -0.016370081 | J44: =J10-J27 -> -0.016370081 | ... O44: =O10-O27 -> -0.0051951051
A45: SELL | B45: Selling Expense | C45: =C11-C28 -> 217.45793 | D45: =D11-D28 -> 217.45793 | E45: =E11-E28 -> 147.10321 | F45: =F11-F28 -> 268.28404 | G45: =G11-G28 -> 199.07864 | H45: =H11-H28 -> 248.65276 | I45: =I11-I28 -> 254.69136 | J45: =J11-J28 -> 284.13278 | ... O45: =O11-O28 -> 1969.0965
A46: GA | B46: G&A | C46: =C12-C29 -> -86.877747 | D46: =D12-D29 -> -86.877747 | E46: =E12-E29 -> -92.987346 | F46: =F12-F29 -> -51.633673 | G46: =G12-G29 -> -65.201589 | H46: =H12-H29 -> -54.400807 | I46: =I12-I29 -> -32.440806 | J46: =J12-J29 -> -29.623966 | ... O46: =O12-O29 -> -546.07451
...

Sheet 05A_YoY_Analysis
